Workbook

Sheet Revenue Model
A1: SPOTIFY TECHNOLOGY S.A. — REVENUE MODEL
A2: (EUR millions unless noted)
B4: 2021A | C4: 2022A | D4: 2023A | E4: 2024A | F4: 2025A | G4: 2026E | H4: 2027E | I4: 2028E | J4: 2029E | K4: 2030E
A6: REVENUE BY PRODUCT / SEGMENT
A7: Premium Subscribers (M, year-end) | B7: 180 | C7: 205 | D7: 236 | E7: 263 | F7: 290 | G7: 318 | H7: 349 | I7: 381 | J7: 413 | K7: 445
A8: Premium Sub YoY Growth | C8: =IF(B7=0,0,(C7-B7)/B7) | D8: =IF(C7=0,0,(D7-C7)/C7) | E8: =IF(D7=0,0,(E7-D7)/D7) | F8: =IF(E7=0,0,(F7-E7)/E7) | G8: =IF(F7=0,0,(G7-F7)/F7) | H8: =IF(G7=0,0,(H7-G7)/G7) | I8: =IF(H7=0,0,(I7-H7)/H7) | J8: =IF(I7=0,0,(J7-I7)/I7) | K8: =IF(J7=0,0,(K7-J7)/J7)
A9: Avg Premium Subscribers (M) | B9: 168 | C9: =(B7+C7)/2 | D9: =(C7+D7)/2 | E9: =(D7+E7)/2 | F9: =(E7+F7)/2 | G9: =(F7+G7)/2 | H9: =(G7+H7)/2 | I9: =(H7+I7)/2 | J9: =(I7+J7)/2 | K9: =(J7+K7)/2
A10: Annual ARPU (EUR/sub) | B10: =B12/B9 | C10: =C12/C9 | D10: =D12/D9 | E10: =E12/E9 | F10: =F12/F9 | G10: 55.5 | H10: 57 | I10: 58.5 | J10: 60 | K10: 61.5
A11: ARPU YoY Growth | C11: =IF(B10=0,0,(C10-B10)/B10) | D11: =IF(C10=0,0,(D10-C10)/C10) | E11: =IF(D10=0,0,(E10-D10)/D10) | F11: =IF(E10=0,0,(F10-E10)/E10) | G11: =IF(F10=0,0,(G10-F10)/F10) | H11: =IF(G10=0,0,(H10-G10)/G10) | I11: =IF(H10=0,0,(I10-H10)/H10) | J11: =IF(I10=0,0,(J10-I10)/I10) | K11: =IF(J10=0,0,(K10-J10)/J10)
A12: Premium Revenue | B12: 8460 | C12: 10251 | D12: 11566 | E12: 13820 | F12: 15100 | G12: =G9*G10 | H12: =H9*H10 | I12: =I9*I10 | J12: =J9*J10 | K12: =K9*K10
A13: Premium Revenue YoY Growth | C13: =IF(B12=0,0,(C12-B12)/B12) | D13: =IF(C12=0,0,(D12-C12)/C12) | E13: =IF(D12=0,0,(E12-D12)/D12) | F13: =IF(E12=0,0,(F12-E12)/E12) | G13: =IF(F12=0,0,(G12-F12)/F12) | H13: =IF(G12=0,0,(H12-G12)/G12) | I13: =IF(H12=0,0,(I12-H12)/H12) | J13: =IF(I12=0,0,(J12-I12)/I12) | K13: =IF(J12=0,0,(K12-J12)/J12)
A15: Ad-Supported MAUs (M, year-end) | B15: 236 | C15: 295 | D15: 364 | E15: 412 | F15: 461 | G15: 510 | H15: 560 | I15: 610 | J15: 660 | K15: 710
A16: Ad MAU YoY Growth | C16: =IF(B15=0,0,(C15-B15)/B15) | D16: =IF(C15=0,0,(D15-C15)/C15) | E16: =IF(D15=0,0,(E15-D15)/D15) | F16: =IF(E15=0,0,(F15-E15)/E15) | G16: =IF(F15=0,0,(G15-F15)/F15) | H16: =IF(G15=0,0,(H15-G15)/G15) | I16: =IF(H15=0,0,(I15-H15)/H15) | J16: =IF(I15=0,0,(J15-I15)/I15) | K16: =IF(J15=0,0,(K15-J15)/J15)
A17: Avg Ad-Supported MAUs (M) | B17: 210 | C17: =(B15+C15)/2 | D17: =(C15+D15)/2 | E17: =(D15+E15)/2 | F17: =(E15+F15)/2 | G17: =(F15+G15)/2 | H17: =(G15+H15)/2 | I17: =(H15+I15)/2 | J17: =(I15+J15)/2 | K17: =(J15+K15)/2
A18: Ad Revenue per MAU (EUR/year) | B18: =B20/B17 | C18: =C20/C17 | D18: =D20/D17 | E18: =E20/E17 | F18: =F20/F17 | G18: 4.4 | H18: 4.6 | I18: 4.8 | J18: 5 | K18: 5.2
A19: Ad RPM YoY Growth | C19: =IF(B18=0,0,(C18-B18)/B18) | D19: =IF(C18=0,0,(D18-C18)/C18) | E19: =IF(D18=0,0,(E18-D18)/D18) | F19: =IF(E18=0,0,(F18-E18)/E18) | G19: =IF(F18=0,0,(G18-F18)/F18) | H19: =IF(G18=0,0,(H18-G18)/G18) | I19: =IF(H18=0,0,(I18-H18)/H18) | J19: =IF(I18=0,0,(J18-I18)/I18) | K19: =IF(J18=0,0,(K18-J18)/J18)
A20: Ad-Supported Revenue | B20: 1208 | C20: 1476 | D20: 1681 | E20: 1853 | F20: 2086 | G20: =G17*G18 | H20: =H17*H18 | I20: =I17*I18 | J20: =J17*J18 | K20: =K17*K18
A21: Ad Revenue YoY Growth | C21: =IF(B20=0,0,(C20-B20)/B20) | D21: =IF(C20=0,0,(D20-C20)/C20) | E21: =IF(D20=0,0,(E20-D20)/D20) | F21: =IF(E20=0,0,(F20-E20)/E20) | G21: =IF(F20=0,0,(G20-F20)/F20) | H21: =IF(G20=0,0,(H20-G20)/G20) | I21: =IF(H20=0,0,(I20-H20)/H20) | J21: =IF(I20=0,0,(J20-I20)/I20) | K21: =IF(J20=0,0,(K20-J20)/J20)
A23: TOTAL REVENUE | B23: 9668 | C23: 11727 | D23: 13247 | E23: 15673 | F23: 17186 | G23: =G12+G20 | H23: =H12+H20 | I23: =I12+I20 | J23: =J12+J20 | K23: =K12+K20
A24: Total Revenue YoY Growth | C24: =IF(B23=0,0,(C23-B23)/B23) | D24: =IF(C23=0,0,(D23-C23)/C23) | E24: =IF(D23=0,0,(E23-D23)/D23) | F24: =IF(E23=0,0,(F23-E23)/E23) | G24: =IF(F23=0,0,(G23-F23)/F23) | H24: =IF(G23=0,0,(H23-G23)/G23) | I24: =IF(H23=0,0,(I23-H23)/H23) | J24: =IF(I23=0,0,(J23-I23)/I23) | K24: =IF(J23=0,0,(K23-J23)/J23)
A25: Premium % of Total | B25: =B12/B23 | C25: =C12/C23 | D25: =D12/D23 | E25: =E12/E23 | F25: =F12/F23 | G25: =G12/G23 | H25: =H12/H23 | I25: =I12/I23 | ... K25: =K12/K23
A26: Ad-Supported % of Total | B26: =B20/B23 | C26: =C20/C23 | D26: =D20/D23 | E26: =E20/E23 | F26: =F20/F23 | G26: =G20/G23 | H26: =H20/H23 | I26: =I20/I23 | ... K26: =K20/K23
A28: Total MAUs (M, year-end) | B28: 406 | C28: 489 | D28: 602 | E28: 675 | F28: 751 | G28: 828 | H28: 909 | I28: 991 | J28: 1073 | K28: 1155
A29: Total MAU YoY Growth | C29: =IF(B28=0,0,(C28-B28)/B28) | D29: =IF(C28=0,0,(D28-C28)/C28) | E29: =IF(D28=0,0,(E28-D28)/D28) | F29: =IF(E28=0,0,(F28-E28)/E28) | G29: =IF(F28=0,0,(G28-F28)/F28) | H29: =IF(G28=0,0,(H28-G28)/G28) | I29: =IF(H28=0,0,(I28-H28)/H28) | J29: =IF(I28=0,0,(J28-I28)/I28) | K29: =IF(J28=0,0,(K28-J28)/J28)
A30: Premium Conversion Rate | B30: =B7/B28 | C30: =C7/C28 | D30: =D7/D28 | E30: =E7/E28 | F30: =F7/F28 | G30: =G7/G28 | H30: =H7/H28 | I30: =I7/I28 | ... K30: =K7/K28
A33: REVENUE BY GEOGRAPHY
A34: Europe | B34: 3673 | C34: 4338 | D34: 4901 | E34: 5642 | F34: 6015 | G34: =G23*G38 | H34: =H23*H38 | I34: =I23*I38 | J34: =J23*J38 | K34: =K23*K38
A35: North America | B35: 2803 | C35: 3518 | D35: 3974 | E35: 4701 | F35: 5327 | G35: =G23*G39 | H35: =H23*H39 | I35: =I23*I39 | J35: =J23*J39 | K35: =K23*K39
A36: Latin America | B36: 1740 | C36: 2110 | D36: 2384 | E36: 2977 | F36: 3265 | G36: =G23*G40 | H36: =H23*H40 | I36: =I23*I40 | J36: =J23*J40 | K36: =K23*K40
A37: Rest of World | B37: 1452 | C37: 1761 | D37: 1988 | E37: 2353 | F37: 2579 | G37: =G23*G41 | H37: =H23*H41 | I37: =I23*I41 | J37: =J23*J41 | K37: =K23*K41
A38: Europe % of Total | B38: =B34/B23 | C38: =C34/C23 | D38: =D34/D23 | E38: =E34/E23 | F38: =F34/F23 | G38: 0.34 | H38: 0.33 | I38: 0.32 | J38: 0.32 | K38: 0.31
A39: North America % of Total | B39: =B35/B23 | C39: =C35/C23 | D39: =D35/D23 | E39: =E35/E23 | F39: =F35/F23 | G39: 0.31 | H39: 0.32 | I39: 0.32 | J39: 0.33 | K39: 0.33
A40: Latin America % of Total | B40: =B36/B23 | C40: =C36/C23 | D40: =D36/D23 | E40: =E36/E23 | F40: =F36/F23 | G40: 0.2 | H40: 0.2 | I40: 0.21 | J40: 0.21 | K40: 0.22
A41: Rest of World % of Total | B41: =B37/B23 | C41: =C37/C23 | D41: =D37/D23 | E41: =E37/E23 | F41: =F37/F23 | G41: =1-G38-G39-G40 | H41: =1-H38-H39-H40 | I41: =1-I38-I39-I40 | J41: =1-J38-J39-J40 | K41: =1-K38-K39-K40
A43: Geo Total (Verification) | B43: =B34+B35+B36+B37 | C43: =C34+C35+C36+C37 | D43: =D34+D35+D36+D37 | E43: =E34+E35+E36+E37 | F43: =F34+F35+F36+F37 | G43: =G34+G35+G36+G37 | H43: =H34+H35+H36+H37 | I43: =I34+I35+I36+I37 | ... K43: =K34+K35+K36+K37
A44: Europe YoY Growth | C44: =IF(B34=0,0,(C34-B34)/B34) | D44: =IF(C34=0,0,(D34-C34)/C34) | E44: =IF(D34=0,0,(E34-D34)/D34) | F44: =IF(E34=0,0,(F34-E34)/E34) | G44: =IF(F34=0,0,(G34-F34)/F34) | H44: =IF(G34=0,0,(H34-G34)/G34) | I44: =IF(H34=0,0,(I34-H34)/H34) | J44: =IF(I34=0,0,(J34-I34)/I34) | K44: =IF(J34=0,0,(K34-J34)/J34)
A45: North America YoY Growth | C45: =IF(B35=0,0,(C35-B35)/B35) | D45: =IF(C35=0,0,(D35-C35)/C35) | E45: =IF(D35=0,0,(E35-D35)/D35) | F45: =IF(E35=0,0,(F35-E35)/E35) | G45: =IF(F35=0,0,(G35-F35)/F35) | H45: =IF(G35=0,0,(H35-G35)/G35) | I45: =IF(H35=0,0,(I35-H35)/H35) | J45: =IF(I35=0,0,(J35-I35)/I35) | K45: =IF(J35=0,0,(K35-J35)/J35)
A46: Latin America YoY Growth | C46: =IF(B36=0,0,(C36-B36)/B36) | D46: =IF(C36=0,0,(D36-C36)/C36) | E46: =IF(D36=0,0,(E36-D36)/D36) | F46: =IF(E36=0,0,(F36-E36)/E36) | G46: =IF(F36=0,0,(G36-F36)/F36) | H46: =IF(G36=0,0,(H36-G36)/G36) | I46: =IF(H36=0,0,(I36-H36)/H36) | J46: =IF(I36=0,0,(J36-I36)/I36) | K46: =IF(J36=0,0,(K36-J36)/J36)
A47: Rest of World YoY Growth | C47: =IF(B37=0,0,(C37-B37)/B37) | D47: =IF(C37=0,0,(D37-C37)/C37) | E47: =IF(D37=0,0,(E37-D37)/D37) | F47: =IF(E37=0,0,(F37-E37)/E37) | G47: =IF(F37=0,0,(G37-F37)/F37) | H47: =IF(G37=0,0,(H37-G37)/G37) | I47: =IF(H37=0,0,(I37-H37)/H37) | J47: =IF(I37=0,0,(J37-I37)/I37) | K47: =IF(J37=0,0,(K37-J37)/J37)
A49: VERIFICATION: Product = Geo Total | B49: =IF(ABS(B23-B43)<1,"OK","ERROR") | C49: =IF(ABS(C23-C43)<1,"OK","ERROR") | D49: =IF(ABS(D23-D43)<1,"OK","ERROR") | E49: =IF(ABS(E23-E43)<1,"OK","ERROR") | F49: =IF(ABS(F23-F43)<1,"OK","ERROR") | G49: =IF(ABS(G23-G43)<1,"OK","ERROR") | H49: =IF(ABS(H23-H43)<1,"OK","ERROR") | I49: =IF(ABS(I23-I43)<1,"OK","ERROR") | ... K49: =IF(ABS(K23-K43)<1,"OK","ERROR")

Sheet Income Statement
A1: SPOTIFY TECHNOLOGY S.A. — INCOME STATEMENT
A2: (EUR millions unless noted)
B4: 2021A | C4: 2022A | D4: 2023A | E4: 2024A | F4: 2025A | G4: 2026E | H4: 2027E | I4: 2028E | J4: 2029E | K4: 2030E
A6: Revenue | B6: ='Revenue Model'!B23 | C6: ='Revenue Model'!C23 | D6: ='Revenue Model'!D23 | E6: ='Revenue Model'!E23 | F6: ='Revenue Model'!F23 | G6: ='Revenue Model'!G23 | H6: ='Revenue Model'!H23 | I6: ='Revenue Model'!I23 | ... K6: ='Revenue Model'!K23
A7: Revenue YoY Growth | C7: =IF(B6=0,0,(C6-B6)/B6) | D7: =IF(C6=0,0,(D6-C6)/C6) | E7: =IF(D6=0,0,(E6-D6)/D6) | F7: =IF(E6=0,0,(F6-E6)/E6) | G7: =IF(F6=0,0,(G6-F6)/F6) | H7: =IF(G6=0,0,(H6-G6)/G6) | I7: =IF(H6=0,0,(I6-H6)/H6) | J7: =IF(I6=0,0,(J6-I6)/I6) | K7: =IF(J6=0,0,(K6-J6)/J6)
A9: Cost of Revenue | B9: -7077 | C9: -8801 | D9: -9800 | E9: -10935 | F9: -11690 | G9: =-G6*(1-G12) | H9: =-H6*(1-H12) | I9: =-I6*(1-I12) | J9: =-J6*(1-J12) | K9: =-K6*(1-K12)
A10: COGS % of Revenue | B10: =-B9/B6 | C10: =-C9/C6 | D10: =-D9/D6 | E10: =-E9/E6 | F10: =-F9/F6 | G10: =-G9/G6 | H10: =-H9/H6 | I10: =-I9/I6 | ... K10: =-K9/K6
A12: Gross Margin % (assumption) | B12: =(B6+B9)/B6 | C12: =(C6+C9)/C6 | D12: =(D6+D9)/D6 | E12: =(E6+E9)/E6 | F12: =(F6+F9)/F6 | G12: 0.325 | H12: 0.33 | I12: 0.335 | J12: 0.34 | K12: 0.345
A13: Gross Profit | B13: =B6+B9 | C13: =C6+C9 | D13: =D6+D9 | E13: =E6+E9 | F13: =F6+F9 | G13: =G6+G9 | H13: =H6+H9 | I13: =I6+I9 | ... K13: =K6+K9
A15: OPERATING EXPENSES
A16: Research & Development | B16: -912 | C16: -1387 | D16: -1606 | E16: -1486 | F16: -1393 | G16: =-G6*G21 | H16: =-H6*H21 | I16: =-I6*I21 | J16: =-J6*J21 | K16: =-K6*K21
A17: Sales & Marketing | B17: -1132 | C17: -1564 | D17: -1599 | E17: -1402 | F17: -1300 | G17: =-G6*G22 | H17: =-H6*H22 | I17: =-I6*I22 | J17: =-J6*J22 | K17: =-K6*K22
A18: General & Administrative | B18: -453 | C18: -634 | D18: -441 | E18: -471 | F18: -605 | G18: =-G6*G23 | H18: =-H6*H23 | I18: =-I6*I23 | J18: =-J6*J23 | K18: =-K6*K23
A19: Total Operating Expenses | B19: =B16+B17+B18 | C19: =C16+C17+C18 | D19: =D16+D17+D18 | E19: =E16+E17+E18 | F19: =F16+F17+F18 | G19: =G16+G17+G18 | H19: =H16+H17+H18 | I19: =I16+I17+I18 | ... K19: =K16+K17+K18
A21: R&D % of Revenue | B21: =-B16/B6 | C21: =-C16/C6 | D21: =-D16/D6 | E21: =-E16/E6 | F21: =-F16/F6 | G21: 0.078 | H21: 0.075 | I21: 0.072 | J21: 0.07 | K21: 0.068
A22: S&M % of Revenue | B22: =-B17/B6 | C22: =-C17/C6 | D22: =-D17/D6 | E22: =-E17/E6 | F22: =-F17/F6 | G22: 0.072 | H22: 0.068 | I22: 0.065 | J22: 0.062 | K22: 0.06
A23: G&A % of Revenue | B23: =-B18/B6 | C23: =-C18/C6 | D23: =-D18/D6 | E23: =-E18/E6 | F23: =-F18/F6 | G23: 0.033 | H23: 0.032 | I23: 0.031 | J23: 0.03 | K23: 0.029
A25: EBITDA | B25: =B31+B28 | C25: =C31+C28 | D25: =D31+D28 | E25: =E31+E28 | F25: =F31+F28 | G25: =G31+G28 | H25: =H31+H28 | I25: =I31+I28 | ... K25: =K31+K28
A26: EBITDA Margin % | B26: =B25/B6 | C26: =C25/C6 | D26: =D25/D6 | E26: =E25/E6 | F26: =F25/F6 | G26: =G25/G6 | H26: =H25/H6 | I26: =I25/I6 | ... K26: =K25/K6
A28: Depreciation & Amortization | B28: 127 | C28: 171 | D28: 158 | E28: 69 | F28: 56 | G28: 50 | H28: 48 | I28: 46 | J28: 44 | K28: 42
A29: Stock-Based Compensation | B29: 223 | C29: 381 | D29: 321 | E29: 267 | F29: 247 | G29: 240 | H29: 235 | I29: 230 | J29: 225 | K29: 220
A31: Operating Income (EBIT) | B31: =B13+B19 | C31: =C13+C19 | D31: =D13+D19 | E31: =E13+E19 | F31: =F13+F19 | G31: =G13+G19 | H31: =H13+H19 | I31: =I13+I19 | ... K31: =K13+K19
A32: Operating Margin % | B32: =B31/B6 | C32: =C31/C6 | D32: =D31/D6 | E32: =E31/E6 | F32: =F31/F6 | G32: =G31/G6 | H32: =H31/H6 | I32: =I31/I6 | ... K32: =K31/K6
A34: Interest Expense | B34: -69 | C34: -41 | D34: -38 | E34: -36 | F34: -31 | G34: -28 | H34: -25 | I34: -22 | J34: -20 | K34: -18
A35: Interest Income | B35: 11 | C35: 47 | D35: 131 | E35: 242 | F35: 268 | G35: 300 | H35: 320 | I35: 340 | J35: 360 | K35: 380
A36: Other Income / (Loss) | B36: 166 | C36: 211 | D36: -100 | E36: -260 | F36: -111 | G36: 20 | H36: 25 | I36: 30 | J36: 35 | K36: 40
A38: Pre-Tax Income | B38: =B31+B34+B35+B36 | C38: =C31+C34+C35+C36 | D38: =D31+D34+D35+D36 | E38: =E31+E34+E35+E36 | F38: =F31+F34+F35+F36 | G38: =G31+G34+G35+G36 | H38: =H31+H34+H35+H36 | I38: =I31+I34+I35+I36 | ... K38: =K31+K34+K35+K36
A39: Pre-Tax Margin % | B39: =B38/B6 | C39: =C38/C6 | D39: =D38/D6 | E39: =E38/E6 | F39: =F38/F6 | G39: =G38/G6 | H39: =H38/H6 | I39: =I38/I6 | ... K39: =K38/K6
A41: Income Tax Expense | B41: -283 | C41: -60 | D41: -27 | E41: -203 | F41: -12 | G41: =-MAX(G38,0)*G42 | H41: =-MAX(H38,0)*H42 | I41: =-MAX(I38,0)*I42 | J41: =-MAX(J38,0)*J42 | K41: =-MAX(K38,0)*K42
A42: Effective Tax Rate | B42: =IF(B38>0,-B41/B38,0) | C42: =IF(C38>0,-C41/C38,0) | D42: =IF(D38>0,-D41/D38,0) | E42: =IF(E38>0,-E41/E38,0) | F42: =IF(F38>0,-F41/F38,0) | G42: 0.12 | H42: 0.14 | I42: 0.15 | J42: 0.16 | K42: 0.17
A44: NET INCOME | B44: =B38+B41 | C44: =C38+C41 | D44: =D38+D41 | E44: =E38+E41 | F44: =F38+F41 | G44: =G38+G41 | H44: =H38+H41 | I44: =I38+I41 | ... K44: =K38+K41
A45: Net Margin % | B45: =B44/B6 | C45: =C44/C6 | D45: =D44/D6 | E45: =E44/E6 | F45: =F44/F6 | G45: =G44/G6 | H45: =H44/H6 | I45: =I44/I6 | ... K45: =K44/K6
A47: Shares Outstanding - Basic (M) | B47: 191 | C47: 193 | D47: 195 | E47: 201 | F47: 205 | G47: 208 | H47: 210 | I47: 212 | J47: 214 | K47: 216
A48: Shares Outstanding - Diluted (M) | B48: 194 | C48: 196 | D48: 195 | E48: 207 | F48: 211 | G48: 214 | H48: 216 | I48: 218 | J48: 220 | K48: 222
A50: EPS - Basic (EUR) | B50: =B44/B47 | C50: =C44/C47 | D50: =D44/D47 | E50: =E44/E47 | F50: =F44/F47 | G50: =G44/G47 | H50: =H44/H47 | I50: =I44/I47 | ... K50: =K44/K47
A51: EPS - Diluted (EUR) | B51: =B44/B48 | C51: =C44/C48 | D51: =D44/D48 | E51: =E44/E48 | F51: =F44/F48 | G51: =G44/G48 | H51: =H44/H48 | I51: =I44/I48 | ... K51: =K44/K48

Sheet Cash Flow
A1: SPOTIFY TECHNOLOGY S.A. — CASH FLOW STATEMENT
A2: (EUR millions)
B4: 2021A | C4: 2022A | D4: 2023A | E4: 2024A | F4: 2025A | G4: 2026E | H4: 2027E | I4: 2028E | J4: 2029E | K4: 2030E
A6: CASH FROM OPERATIONS
A7: Net Income | B7: ='Income Statement'!B44 | C7: ='Income Statement'!C44 | D7: ='Income Statement'!D44 | E7: ='Income Statement'!E44 | F7: ='Income Statement'!F44 | G7: ='Income Statement'!G44 | H7: ='Income Statement'!H44 | I7: ='Income Statement'!I44 | ... K7: ='Income Statement'!K44
A8: Depreciation & Amortization | B8: ='Income Statement'!B28 | C8: ='Income Statement'!C28 | D8: ='Income Statement'!D28 | E8: ='Income Statement'!E28 | F8: ='Income Statement'!F28 | G8: ='Income Statement'!G28 | H8: ='Income Statement'!H28 | I8: ='Income Statement'!I28 | ... K8: ='Income Statement'!K28
A9: Stock-Based Compensation | B9: ='Income Statement'!B29 | C9: ='Income Statement'!C29 | D9: ='Income Statement'!D29 | E9: ='Income Statement'!E29 | F9: ='Income Statement'!F29 | G9: ='Income Statement'!G29 | H9: ='Income Statement'!H29 | I9: ='Income Statement'!I29 | ... K9: ='Income Statement'!K29
A10: Other Non-Cash Items | B10: 63 | C10: -267 | D10: 117 | E10: 356 | F10: 116 | G10: 50 | H10: 50 | I10: 50 | J10: 50 | K10: 50
A12: Changes in Working Capital:
A13: Accounts Receivable | B13: -245 | C13: -84 | D13: -145 | E13: 145 | F13: -115 | G13: =('Revenue Model'!G23-'Revenue Model'!F23)*-0.03 | H13: =('Revenue Model'!H23-'Revenue Model'!G23)*-0.03 | I13: =('Revenue Model'!I23-'Revenue Model'!H23)*-0.03 | J13: =('Revenue Model'!J23-'Revenue Model'!I23)*-0.03 | K13: =('Revenue Model'!K23-'Revenue Model'!J23)*-0.03
A14: Accounts Payable | B14: 137 | C14: 226 | D14: 501 | E14: 183 | F14: 281 | G14: =('Revenue Model'!G23-'Revenue Model'!F23)*0.04 | H14: =('Revenue Model'!H23-'Revenue Model'!G23)*0.04 | I14: =('Revenue Model'!I23-'Revenue Model'!H23)*0.04 | J14: =('Revenue Model'!J23-'Revenue Model'!I23)*0.04 | K14: =('Revenue Model'!K23-'Revenue Model'!J23)*0.04
A15: Deferred Revenue | B15: 67 | C15: 52 | D15: 113 | E15: 45 | F15: 60 | G15: =('Revenue Model'!G23-'Revenue Model'!F23)*0.02 | H15: =('Revenue Model'!H23-'Revenue Model'!G23)*0.02 | I15: =('Revenue Model'!I23-'Revenue Model'!H23)*0.02 | J15: =('Revenue Model'!J23-'Revenue Model'!I23)*0.02 | K15: =('Revenue Model'!K23-'Revenue Model'!J23)*0.02
A17: Cash from Operations (CFO) | B17: =B7+B8+B9+B10+B13+B14+B15 | C17: =C7+C8+C9+C10+C13+C14+C15 | D17: =D7+D8+D9+D10+D13+D14+D15 | E17: =E7+E8+E9+E10+E13+E14+E15 | F17: =F7+F8+F9+F10+F13+F14+F15 | G17: =G7+G8+G9+G10+G13+G14+G15 | H17: =H7+H8+H9+H10+H13+H14+H15 | I17: =I7+I8+I9+I10+I13+I14+I15 | ... K17: =K7+K8+K9+K10+K13+K14+K15
A19: CASH FROM INVESTING
A20: Capital Expenditures | B20: -85 | C20: -25 | D20: -6 | E20: -17 | F20: -61 | G20: -70 | H20: -80 | I20: -90 | J20: -100 | K20: -110
A21: Acquisitions | B21: -115 | C21: -306 | D21: -7 | E21: -10 | F21: -18 | G21: -20 | H21: -25 | I21: -30 | J21: -35 | K21: -40
A22: Securities / Other Investing | B22: 22 | C22: -89 | D22: -211 | E22: -1471 | F22: -1726 | G22: -500 | H22: -400 | I22: -300 | J22: -200 | K22: -100
A24: Cash from Investing (CFI) | B24: =B20+B21+B22 | C24: =C20+C21+C22 | D24: =D20+D21+D22 | E24: =E20+E21+E22 | F24: =F20+F21+F22 | G24: =G20+G21+G22 | H24: =H20+H21+H22 | I24: =I20+I21+I22 | ... K24: =K20+K21+K22
A26: FREE CASH FLOW (CFO - CapEx) | B26: =B17+B20 | C26: =C17+C20 | D26: =D17+D20 | E26: =E17+E20 | F26: =F17+F20 | G26: =G17+G20 | H26: =H17+H20 | I26: =I17+I20 | ... K26: =K17+K20
A27: FCF Margin % | B27: =B26/'Revenue Model'!B23 | C27: =C26/'Revenue Model'!C23 | D27: =D26/'Revenue Model'!D23 | E27: =E26/'Revenue Model'!E23 | F27: =F26/'Revenue Model'!F23 | G27: =G26/'Revenue Model'!G23 | H27: =H26/'Revenue Model'!H23 | I27: =I26/'Revenue Model'!I23 | ... K27: =K26/'Revenue Model'!K23
A29: CASH FROM FINANCING
A30: Debt Repayment | B30: -35 | C30: -43 | D30: -66 | E30: -69 | F30: -73 | G30: -75 | H30: -75 | I30: -75 | J30: -75 | K30: -75
A31: Stock Issuance (Options/RSUs) | B31: 167 | C31: 43 | D31: 366 | E31: 933 | F31: 372 | G31: 100 | H31: 80 | I31: 60 | J31: 40 | K31: 20
A32: Share Repurchases | B32: -143 | C32: -42 | D32: -68 | E32: -135 | F32: -680 | G32: -800 | H32: -900 | I32: -1000 | J32: -1100 | K32: -1200
A33: Other Financing | B33: 1261 | C33: -2 | D33: 2 | E33: 0 | F33: 0 | G33: 0 | H33: 0 | I33: 0 | J33: 0 | K33: 0
A35: Cash from Financing (CFF) | B35: =B30+B31+B32+B33 | C35: =C30+C31+C32+C33 | D35: =D30+D31+D32+D33 | E35: =E30+E31+E32+E33 | F35: =F30+F31+F32+F33 | G35: =G30+G31+G32+G33 | H35: =H30+H31+H32+H33 | I35: =I30+I31+I32+I33 | ... K35: =K30+K31+K32+K33
A37: Net Change in Cash | B37: =B17+B24+B35 | C37: =C17+C24+C35 | D37: =D17+D24+D35 | E37: =E17+E24+E35 | F37: =F17+F24+F35 | G37: =G17+G24+G35 | H37: =H17+H24+H35 | I37: =I17+I24+I35 | ... K37: =K17+K24+K35
A39: Beginning Cash & Equivalents | B39: 1151 | C39: 2744 | D39: 2483 | E39: 3114 | F39: 4781 | G39: =F40 | H39: =G40 | I39: =H40 | J39: =I40 | K39: =J40
A40: Ending Cash & Equivalents | B40: =B39+B37 | C40: =C39+C37 | D40: =D39+D37 | E40: =E39+E37 | F40: =F39+F37 | G40: =G39+G37 | H40: =H39+H37 | I40: =I39+I37 | ... K40: =K39+K37

Sheet Balance Sheet
A1: SPOTIFY TECHNOLOGY S.A. — BALANCE SHEET
A2: (EUR millions)
B4: 2021A | C4: 2022A | D4: 2023A | E4: 2024A | F4: 2025A | G4: 2026E | H4: 2027E | I4: 2028E | J4: 2029E | K4: 2030E
A6: CURRENT ASSETS
A7: Cash & Equivalents | B7: 2744 | C7: 2483 | D7: 3114 | E7: 4781 | F7: 5258 | G7: ='Cash Flow'!G40 | H7: ='Cash Flow'!H40 | I7: ='Cash Flow'!I40 | J7: ='Cash Flow'!J40 | K7: ='Cash Flow'!K40
A8: Short-Term Investments | B8: 689 | C8: 867 | D8: 859 | E8: 1972 | F8: 2458 | G8: 2800 | H8: 3200 | I8: 3600 | J8: 4000 | K8: 4400
A9: Accounts Receivable | B9: 437 | C9: 502 | D9: 602 | E9: 540 | F9: 536 | G9: ='Revenue Model'!G23*0.028 | H9: ='Revenue Model'!H23*0.028 | I9: ='Revenue Model'!I23*0.028 | J9: ='Revenue Model'!J23*0.028 | K9: ='Revenue Model'!K23*0.028
A10: Prepaid Expenses | B10: 74 | C10: 89 | D10: 64 | E10: 71 | F10: 75 | G10: 80 | H10: 80 | I10: 80 | J10: 80 | K10: 80
A11: Other Current Assets | B11: 239 | C11: 218 | D11: 345 | E11: 756 | F11: 1787 | G11: 800 | H11: 800 | I11: 800 | J11: 800 | K11: 800
A13: Total Current Assets | B13: =SUM(B7:B11) | C13: =SUM(C7:C11) | D13: =SUM(D7:D11) | E13: =SUM(E7:E11) | F13: =SUM(F7:F11) | G13: =SUM(G7:G11) | H13: =SUM(H7:H11) | I13: =SUM(I7:I11) | ... K13: =SUM(K7:K11)
A15: NON-CURRENT ASSETS
A16: Property, Plant & Equipment | B16: 809 | C16: 765 | D16: 547 | E16: 414 | F16: 422 | G16: 400 | H16: 390 | I16: 380 | J16: 370 | K16: 360
A17: Long-Term Investments | B17: 916 | C17: 1138 | D17: 1215 | E17: 1635 | F17: 2181 | G17: 2500 | H17: 2800 | I17: 3100 | J17: 3400 | K17: 3700
A18: Goodwill | B18: 894 | C18: 1168 | D18: 1137 | E18: 1201 | F18: 1083 | G18: 1100 | H18: 1120 | I18: 1140 | J18: 1160 | K18: 1180
A19: Intangible Assets | B19: 58 | C19: 108 | D19: 71 | E19: 40 | F19: 29 | G19: 25 | H19: 25 | I19: 25 | J19: 25 | K19: 25
A20: Deferred Tax Assets | B20: 13 | C20: 8 | D20: 28 | E20: 186 | F20: 662 | G20: 700 | H20: 720 | I20: 740 | J20: 760 | K20: 780
A21: Other Non-Current Assets | B21: 297 | C21: 292 | D21: 364 | E21: 409 | F21: 524 | G21: 500 | H21: 500 | I21: 500 | J21: 500 | K21: 500
A23: Total Non-Current Assets | B23: =SUM(B16:B21) | C23: =SUM(C16:C21) | D23: =SUM(D16:D21) | E23: =SUM(E16:E21) | F23: =SUM(F16:F21) | G23: =SUM(G16:G21) | H23: =SUM(H16:H21) | I23: =SUM(I16:I21) | ... K23: =SUM(K16:K21)
A25: TOTAL ASSETS | B25: =B13+B23 | C25: =C13+C23 | D25: =D13+D23 | E25: =E13+E23 | F25: =F13+F23 | G25: =G13+G23 | H25: =H13+H23 | I25: =I13+I23 | ... K25: =K13+K23
A27: CURRENT LIABILITIES
A28: Accounts Payable | B28: 534 | C28: 588 | D28: 662 | E28: 933 | F28: 783 | G28: ='Revenue Model'!G23*0.045 | H28: ='Revenue Model'!H23*0.045 | I28: ='Revenue Model'!I23*0.045 | J28: ='Revenue Model'!J23*0.045 | K28: ='Revenue Model'!K23*0.045
A29: Accrued Expenses | B29: 2034 | C29: 2287 | D29: 2666 | E29: 2607 | F29: 2904 | G29: ='Revenue Model'!G23*0.16 | H29: ='Revenue Model'!H23*0.16 | I29: ='Revenue Model'!I23*0.16 | J29: ='Revenue Model'!J23*0.16 | K29: ='Revenue Model'!K23*0.16
A30: Deferred Revenue | B30: 458 | C30: 520 | D30: 622 | E30: 683 | F30: 711 | G30: ='Revenue Model'!G23*0.038 | H30: ='Revenue Model'!H23*0.038 | I30: ='Revenue Model'!I23*0.038 | J30: ='Revenue Model'!J23*0.038 | K30: ='Revenue Model'!K23*0.038
A31: Current Portion of LT Debt | B31: 0 | C31: 0 | D31: 0 | E31: 0 | F31: 1458 | G31: 0 | H31: 0 | I31: 0 | J31: 0 | K31: 0
A32: Current Lease Liabilities | B32: 44 | C32: 58 | D32: 65 | E32: 75 | F32: 65 | G32: 60 | H32: 60 | I32: 60 | J32: 60 | K32: 60
A33: Other Current Liabilities | B33: 156 | C33: 63 | D33: 75 | E33: 152 | F33: 164 | G33: 150 | H33: 150 | I33: 150 | J33: 150 | K33: 150
A35: Total Current Liabilities | B35: =SUM(B28:B33) | C35: =SUM(C28:C33) | D35: =SUM(D28:D33) | E35: =SUM(E28:E33) | F35: =SUM(F28:F33) | G35: =SUM(G28:G33) | H35: =SUM(H28:H33) | I35: =SUM(I28:I33) | ... K35: =SUM(K28:K33)
A37: NON-CURRENT LIABILITIES
A38: Long-Term Debt | B38: 1202 | C38: 1128 | D38: 1203 | E38: 1539 | F38: 0 | G38: 0 | H38: 0 | I38: 0 | J38: 0 | K38: 0
A39: Long-Term Lease Liabilities | B39: 579 | C39: 555 | D39: 493 | E39: 462 | F39: 433 | G39: 400 | H39: 370 | I39: 340 | J39: 310 | K39: 280
A40: Deferred Tax Liabilities | B40: 0 | C40: 5 | D40: 8 | E40: 21 | F40: 163 | G40: 180 | H40: 180 | I40: 180 | J40: 180 | K40: 180
A41: Other Non-Current Liabilities | B41: 44 | C41: 31 | D41: 29 | E41: 8 | F41: 5 | G41: 5 | H41: 5 | I41: 5 | J41: 5 | K41: 5
A43: Total Non-Current Liabilities | B43: =SUM(B38:B41) | C43: =SUM(C38:C41) | D43: =SUM(D38:D41) | E43: =SUM(E38:E41) | F43: =SUM(F38:F41) | G43: =SUM(G38:G41) | H43: =SUM(H38:H41) | I43: =SUM(I38:I41) | ... K43: =SUM(K38:K41)
A45: TOTAL LIABILITIES | B45: =B35+B43 | C45: =C35+C43 | D45: =D35+D43 | E45: =E35+E43 | F45: =F35+F43 | G45: =G35+G43 | H45: =H35+H43 | I45: =I35+I43 | ... K45: =K35+K43
A47: SHAREHOLDERS' EQUITY
A48: Additional Paid-In Capital | B48: 4746 | C48: 4789 | D48: 5155 | E48: 6124 | F48: 6496 | G48: =F48+'Income Statement'!G29+'Cash Flow'!G31 | H48: =G48+'Income Statement'!H29+'Cash Flow'!H31 | I48: =H48+'Income Statement'!I29+'Cash Flow'!I31 | J48: =I48+'Income Statement'!J29+'Cash Flow'!J31 | K48: =J48+'Income Statement'!K29+'Cash Flow'!K31
A49: Retained Earnings | B49: -3220 | C49: -3647 | D49: -4182 | E49: -3044 | F49: -832 | G49: =F49+'Income Statement'!G44 | H49: =G49+'Income Statement'!H44 | I49: =H49+'Income Statement'!I44 | J49: =I49+'Income Statement'!J44 | K49: =J49+'Income Statement'!K44
A50: Treasury Stock | B50: -260 | C50: -262 | D50: -262 | E50: -262 | F50: -701 | G50: =F50+'Cash Flow'!G32 | H50: =G50+'Cash Flow'!H32 | I50: =H50+'Cash Flow'!I32 | J50: =I50+'Cash Flow'!J32 | K50: =J50+'Cash Flow'!K32
A51: AOCI & Other Equity | B51: 853 | C51: 1521 | D51: 1812 | E51: 2707 | F51: 3366 | G51: 3500 | H51: 3600 | I51: 3700 | J51: 3800 | K51: 3900
A53: TOTAL SHAREHOLDERS' EQUITY | B53: =B48+B49+B50+B51 | C53: =C48+C49+C50+C51 | D53: =D48+D49+D50+D51 | E53: =E48+E49+E50+E51 | F53: =F48+F49+F50+F51 | G53: =G48+G49+G50+G51 | H53: =H48+H49+H50+H51 | I53: =I48+I49+I50+I51 | ... K53: =K48+K49+K50+K51
...

Sheet Scenarios
A1: SPOTIFY TECHNOLOGY S.A. — SCENARIO ANALYSIS
A2: (EUR millions unless noted)
A4: Assumption | B4: Bull | C4: Base | D4: Bear | E4: Rationale
A5: Revenue CAGR 2026-2030 | B5: 0.14 | C5: 0.1 | D5: 0.07 | E5: Bull: pricing power + ad growth; Base: steady growth; Bear: competition/macro slowdown
A6: Gross Margin 2030E | B6: 0.38 | C6: 0.345 | D6: 0.3 | E6: Bull: better licensing terms; Base: gradual improvement; Bear: label cost pressure
A7: EBITDA Margin 2030E | B7: 0.22 | C7: 0.17 | D7: 0.12 | E7: Bull: strong OpLev; Base: continued discipline; Bear: reinvestment/competition
A8: Premium Sub Growth CAGR | B8: 0.12 | C8: 0.09 | D8: 0.06 | E8: Bull: TAM expansion + new markets; Base: mature growth; Bear: saturation
A9: ARPU Growth (annual) | B9: 0.05 | C9: 0.03 | D9: 0.01 | E9: Bull: aggressive pricing; Base: modest price increases; Bear: mix shift to lower ARPU regions
A10: Ad Revenue Growth CAGR | B10: 0.18 | C10: 0.12 | D10: 0.06 | E10: Bull: programmatic + podcast ads; Base: steady share gains; Bear: ad market weakness
A11: Tax Rate 2030E | B11: 0.15 | C11: 0.17 | D11: 0.2 | E11: Bull: tax-efficient structure; Base: normalized; Bear: higher global tax rates
A14: Output Metric (2030E) | B14: Bull | C14: Base | D14: Bear
A15: 2030E Revenue (EUR M) | B15: =17186*(1+B5)^5 | C15: =17186*(1+C5)^5 | D15: =17186*(1+D5)^5
A16: 2030E Gross Profit (EUR M) | B16: =B15*B6 | C16: =C15*C6 | D16: =D15*D6
A17: 2030E EBITDA (EUR M) | B17: =B15*B7 | C17: =C15*C7 | D17: =D15*D7
A18: 2030E Net Income (EUR M) | B18: =B17*(1-B11) | C18: =C17*(1-C11) | D18: =D17*(1-D11)
A19: 2030E EPS (EUR) | B19: =B18/216 | C19: =C18/216 | D19: =D18/216
A20: 2030E FCF (EUR M) | B20: =B18+50-110 | C20: =C18+50-110 | D20: =D18+50-110
A21: Cumulative FCF 2026-2030 (EUR M) | B21: =B20*4.2 | C21: =C20*3.5 | D21: =D20*2.8
A22: 2030E Premium Subs (M) | B22: =290*(1+B8)^5 | C22: =290*(1+C8)^5 | D22: =290*(1+D8)^5
A25: SCENARIO RATIONALE
A26: Bull Case:
A27: Spotify successfully leverages pricing power across all tiers, accelerates ad monetization through programmatic and podcast advertising, expands audiobook revenue, and achieves significant operating leverage through cost discipline. Premium subscriber growth remains robust driven by emerging market penetration and new product features (AI DJ, etc.). Content costs decline as % of revenue due to better label negotiations.
A28: Base Case:
A29: Spotify maintains steady subscriber and MAU growth in line with recent trends. Gradual margin improvement continues as the company benefits from 2023-2024 restructuring. ARPU grows modestly through periodic price increases. Ad-supported revenue grows but remains ~12% of total. Content costs remain ~67% of revenue. Company generates consistent and growing free cash flow.
A30: Bear Case:
A31: Increased competition from Apple Music, YouTube Music, and Amazon Music pressures subscriber growth and limits pricing power. Label negotiations become more challenging, keeping content costs elevated. Ad market softness limits ad revenue growth. Macro headwinds in key markets slow MAU growth. Company must reinvest heavily in content and features to maintain market share, limiting margin expansion.

Sheet DCF Inputs
A1: SPOTIFY TECHNOLOGY S.A. — DCF INPUTS
A2: (EUR millions)
B4: 2021A | C4: 2022A | D4: 2023A | E4: 2024A | F4: 2025A | G4: 2026E | H4: 2027E | I4: 2028E | J4: 2029E | K4: 2030E
A6: EBIT (Operating Income) | B6: ='Income Statement'!B31 | C6: ='Income Statement'!C31 | D6: ='Income Statement'!D31 | E6: ='Income Statement'!E31 | F6: ='Income Statement'!F31 | G6: ='Income Statement'!G31 | H6: ='Income Statement'!H31 | I6: ='Income Statement'!I31 | ... K6: ='Income Statement'!K31
A7: Tax Rate | B7: ='Income Statement'!B42 | C7: ='Income Statement'!C42 | D7: ='Income Statement'!D42 | E7: ='Income Statement'!E42 | F7: ='Income Statement'!F42 | G7: ='Income Statement'!G42 | H7: ='Income Statement'!H42 | I7: ='Income Statement'!I42 | ... K7: ='Income Statement'!K42
A8: NOPAT (EBIT * (1 - Tax Rate)) | B8: =MAX(B6,0)*(1-B7) | C8: =MAX(C6,0)*(1-C7) | D8: =MAX(D6,0)*(1-D7) | E8: =MAX(E6,0)*(1-E7) | F8: =MAX(F6,0)*(1-F7) | G8: =MAX(G6,0)*(1-G7) | H8: =MAX(H6,0)*(1-H7) | I8: =MAX(I6,0)*(1-I7) | ... K8: =MAX(K6,0)*(1-K7)
A10: (+) Depreciation & Amortization | B10: ='Income Statement'!B28 | C10: ='Income Statement'!C28 | D10: ='Income Statement'!D28 | E10: ='Income Statement'!E28 | F10: ='Income Statement'!F28 | G10: ='Income Statement'!G28 | H10: ='Income Statement'!H28 | I10: ='Income Statement'!I28 | ... K10: ='Income Statement'!K28
A11: (-) Capital Expenditures | B11: ='Cash Flow'!B20 | C11: ='Cash Flow'!C20 | D11: ='Cash Flow'!D20 | E11: ='Cash Flow'!E20 | F11: ='Cash Flow'!F20 | G11: ='Cash Flow'!G20 | H11: ='Cash Flow'!H20 | I11: ='Cash Flow'!I20 | ... K11: ='Cash Flow'!K20
A12: (-) Change in Net Working Capital | B12: 0 | C12: ='Cash Flow'!C13+'Cash Flow'!C14+'Cash Flow'!C15 | D12: ='Cash Flow'!D13+'Cash Flow'!D14+'Cash Flow'!D15 | E12: ='Cash Flow'!E13+'Cash Flow'!E14+'Cash Flow'!E15 | F12: ='Cash Flow'!F13+'Cash Flow'!F14+'Cash Flow'!F15 | G12: ='Cash Flow'!G13+'Cash Flow'!G14+'Cash Flow'!G15 | H12: ='Cash Flow'!H13+'Cash Flow'!H14+'Cash Flow'!H15 | I12: ='Cash Flow'!I13+'Cash Flow'!I14+'Cash Flow'!I15 | J12: ='Cash Flow'!J13+'Cash Flow'!J14+'Cash Flow'!J15 | K12: ='Cash Flow'!K13+'Cash Flow'!K14+'Cash Flow'!K15
A14: UNLEVERED FREE CASH FLOW | B14: =B8+B10+B11+B12 | C14: =C8+C10+C11+C12 | D14: =D8+D10+D11+D12 | E14: =E8+E10+E11+E12 | F14: =F8+F10+F11+F12 | G14: =G8+G10+G11+G12 | H14: =H8+H10+H11+H12 | I14: =I8+I10+I11+I12 | ... K14: =K8+K10+K11+K12
A15: UFCF Margin % | B15: =B14/'Revenue Model'!B23 | C15: =C14/'Revenue Model'!C23 | D15: =D14/'Revenue Model'!D23 | E15: =E14/'Revenue Model'!E23 | F15: =F14/'Revenue Model'!F23 | G15: =G14/'Revenue Model'!G23 | H15: =H14/'Revenue Model'!H23 | I15: =I14/'Revenue Model'!I23 | ... K15: =K14/'Revenue Model'!K23
A18: TERMINAL YEAR METRICS (2030E)
A19: Revenue | B19: ='Revenue Model'!K23
A20: Revenue Growth (terminal) | B20: 0.04
A21: EBITDA | B21: ='Income Statement'!K25
A22: EBITDA Margin | B22: ='Income Statement'!K25/'Revenue Model'!K23
A23: EBIT | B23: ='Income Statement'!K31
A24: EBIT Margin | B24: ='Income Statement'!K31/'Revenue Model'!K23
A25: Unlevered FCF | B25: =K14
A26: UFCF Margin | B26: =K14/'Revenue Model'!K23
A27: D&A | B27: ='Income Statement'!K28
A28: CapEx | B28: ='Cash Flow'!K20
A31: DCF VALUATION ASSUMPTIONS
A32: WACC (Discount Rate) | B32: 0.1
A33: Terminal Growth Rate | B33: 0.04
A34: Risk-Free Rate | B34: 0.035
A35: Equity Risk Premium | B35: 0.055
A36: Beta (Levered) | B36: 1.15
A37: Cost of Equity | B37: 0.098
A38: Cost of Debt (pre-tax) | B38: 0.035
A39: Debt/Total Capital | B39: 0.05
A40: Shares Outstanding (M) | B40: 216
